INFO:telegram.ext.Application:Application is stopping. This might take a moment.
INFO:telegram.ext.Application:Application.stop() complete
INFO:telegram.ext.Application:Application started
INFO:__main__:Пользователь @golovinovY: запустить приложение
INFO:__main__:Пользователь @golovinovY: показать текущий список вещей
INFO:__main__:Пользователь @golovinovY: добавить вещь в список с сообщением 'rogovshop1'. Магазин: Rogov
INFO:__main__:Пользователь @golovinovY: показать текущий список вещей
INFO:__main__:Пользователь @golovinovY: добавить вещь в список с сообщением 'rogovshop8899'. Магазин: Rogov
INFO:__main__:Пользователь @golovinovY: показать текущий список вещей
INFO:__main__:Пользователь @golovinovY: показать текущий список вещей
INFO:__main__:Пользователь @golovinovY: удалить вещь из списка с сообщением '4'
INFO:__main__:Пользователь @golovinovY: показать текущий список вещей
INFO:__main__:Пользователь @golovinovY: показать текущий список вещей
INFO:__main__:Пользователь @golovinovY: показать видео-гайд
ERROR:__main__:Ошибка! Пользователь @golovinovY:
Traceback (most recent call last):
  File "/home/yyy/Desktop/app_with_git/venv/lib/python3.9/site-packages/httpx/_transports/default.py", line 67, in map_httpcore_exceptions
    yield
  File "/home/yyy/Desktop/app_with_git/venv/lib/python3.9/site-packages/httpx/_transports/default.py", line 371, in handle_async_request
    resp = await self._pool.handle_async_request(req)
  File "/home/yyy/Desktop/app_with_git/venv/lib/python3.9/site-packages/httpcore/_async/connection_pool.py", line 216, in handle_async_request
    raise exc from None
  File "/home/yyy/Desktop/app_with_git/venv/lib/python3.9/site-packages/httpcore/_async/connection_pool.py", line 196, in handle_async_request
    response = await connection.handle_async_request(
  File "/home/yyy/Desktop/app_with_git/venv/lib/python3.9/site-packages/httpcore/_async/connection.py", line 101, in handle_async_request
    return await self._connection.handle_async_request(request)
  File "/home/yyy/Desktop/app_with_git/venv/lib/python3.9/site-packages/httpcore/_async/http11.py", line 143, in handle_async_request
    raise exc
  File "/home/yyy/Desktop/app_with_git/venv/lib/python3.9/site-packages/httpcore/_async/http11.py", line 95, in handle_async_request
    await self._send_request_body(**kwargs)
  File "/home/yyy/Desktop/app_with_git/venv/lib/python3.9/site-packages/httpcore/_async/http11.py", line 166, in _send_request_body
    await self._send_event(event, timeout=timeout)
  File "/home/yyy/Desktop/app_with_git/venv/lib/python3.9/site-packages/httpcore/_async/http11.py", line 175, in _send_event
    await self._network_stream.write(bytes_to_send, timeout=timeout)
  File "/home/yyy/Desktop/app_with_git/venv/lib/python3.9/site-packages/httpcore/_backends/anyio.py", line 51, in write
    await self._stream.send(item=buffer)
  File "/usr/lib/python3.9/contextlib.py", line 135, in __exit__
    self.gen.throw(type, value, traceback)
  File "/home/yyy/Desktop/app_with_git/venv/lib/python3.9/site-packages/httpcore/_exceptions.py", line 14, in map_exceptions
    raise to_exc(exc) from exc
httpcore.WriteTimeout

The above exception was the direct cause of the following exception:

Traceback (most recent call last):
  File "/home/yyy/Desktop/app_with_git/venv/lib/python3.9/site-packages/telegram/request/_httpxrequest.py", line 268, in do_request
    res = await self._client.request(
  File "/home/yyy/Desktop/app_with_git/venv/lib/python3.9/site-packages/httpx/_client.py", line 1559, in request
    return await self.send(request, auth=auth, follow_redirects=follow_redirects)
  File "/home/yyy/Desktop/app_with_git/venv/lib/python3.9/site-packages/httpx/_client.py", line 1646, in send
    response = await self._send_handling_auth(
  File "/home/yyy/Desktop/app_with_git/venv/lib/python3.9/site-packages/httpx/_client.py", line 1674, in _send_handling_auth
    response = await self._send_handling_redirects(
  File "/home/yyy/Desktop/app_with_git/venv/lib/python3.9/site-packages/httpx/_client.py", line 1711, in _send_handling_redirects
    response = await self._send_single_request(request)
  File "/home/yyy/Desktop/app_with_git/venv/lib/python3.9/site-packages/httpx/_client.py", line 1748, in _send_single_request
    response = await transport.handle_async_request(request)
  File "/home/yyy/Desktop/app_with_git/venv/lib/python3.9/site-packages/httpx/_transports/default.py", line 371, in handle_async_request
    resp = await self._pool.handle_async_request(req)
  File "/usr/lib/python3.9/contextlib.py", line 135, in __exit__
    self.gen.throw(type, value, traceback)
  File "/home/yyy/Desktop/app_with_git/venv/lib/python3.9/site-packages/httpx/_transports/default.py", line 84, in map_httpcore_exceptions
    raise mapped_exc(message) from exc
httpx.WriteTimeout

The above exception was the direct cause of the following exception:

Traceback (most recent call last):
  File "/home/yyy/Desktop/app_with_git/venv/lib/python3.9/site-packages/telegram/ext/_application.py", line 1264, in process_update
    await coroutine
  File "/home/yyy/Desktop/app_with_git/venv/lib/python3.9/site-packages/telegram/ext/_handlers/conversationhandler.py", line 857, in handle_update
    new_state: object = await handler.handle_update(
  File "/home/yyy/Desktop/app_with_git/venv/lib/python3.9/site-packages/telegram/ext/_handlers/basehandler.py", line 157, in handle_update
    return await self.callback(update, context)
  File "/home/yyy/Desktop/app_with_git/app/telegram_bot/main_bot.py", line 315, in send_help_video
    await context.bot.send_video(
  File "/home/yyy/Desktop/app_with_git/venv/lib/python3.9/site-packages/telegram/ext/_extbot.py", line 3064, in send_video
    return await super().send_video(
  File "/home/yyy/Desktop/app_with_git/venv/lib/python3.9/site-packages/telegram/_bot.py", line 542, in decorator
    result = await func(self, *args, **kwargs)
  File "/home/yyy/Desktop/app_with_git/venv/lib/python3.9/site-packages/telegram/_bot.py", line 1932, in send_video
    return await self._send_message(
  File "/home/yyy/Desktop/app_with_git/venv/lib/python3.9/site-packages/telegram/ext/_extbot.py", line 581, in _send_message
    result = await super()._send_message(
  File "/home/yyy/Desktop/app_with_git/venv/lib/python3.9/site-packages/telegram/_bot.py", line 736, in _send_message
    result = await self._post(
  File "/home/yyy/Desktop/app_with_git/venv/lib/python3.9/site-packages/telegram/_bot.py", line 630, in _post
    return await self._do_post(
  File "/home/yyy/Desktop/app_with_git/venv/lib/python3.9/site-packages/telegram/ext/_extbot.py", line 347, in _do_post
    return await super()._do_post(
  File "/home/yyy/Desktop/app_with_git/venv/lib/python3.9/site-packages/telegram/_bot.py", line 658, in _do_post
    return await request.post(
  File "/home/yyy/Desktop/app_with_git/venv/lib/python3.9/site-packages/telegram/request/_baserequest.py", line 200, in post
    result = await self._request_wrapper(
  File "/home/yyy/Desktop/app_with_git/venv/lib/python3.9/site-packages/telegram/request/_baserequest.py", line 340, in _request_wrapper
    raise exc
  File "/home/yyy/Desktop/app_with_git/venv/lib/python3.9/site-packages/telegram/request/_baserequest.py", line 330, in _request_wrapper
    code, payload = await self.do_request(
  File "/home/yyy/Desktop/app_with_git/venv/lib/python3.9/site-packages/telegram/request/_httpxrequest.py", line 285, in do_request
    raise TimedOut from err
telegram.error.TimedOut: Timed out
INFO:telegram.ext.Application:Application is stopping. This might take a moment.
INFO:telegram.ext.Application:Application.stop() complete
INFO:telegram.ext.Application:Application started
INFO:__main__:Пользователь @golovinovY: запустить приложение
INFO:__main__:Пользователь @golovinovY: показать текущий список вещей
ERROR:__main__:Ошибка! Пользователь @golovinovY:
Traceback (most recent call last):
  File "/home/yyy/Desktop/app_with_git/venv/lib/python3.9/site-packages/telegram/ext/_application.py", line 1264, in process_update
    await coroutine
  File "/home/yyy/Desktop/app_with_git/venv/lib/python3.9/site-packages/telegram/ext/_handlers/conversationhandler.py", line 857, in handle_update
    new_state: object = await handler.handle_update(
  File "/home/yyy/Desktop/app_with_git/venv/lib/python3.9/site-packages/telegram/ext/_handlers/basehandler.py", line 157, in handle_update
    return await self.callback(update, context)
  File "/home/yyy/Desktop/app_with_git/app/telegram_bot/main_bot.py", line 124, in show_show_menu
    message_text, context.user_data["current_user_list_of_items"] = await get_current_user_list_of_items_and_message(update.effective_user.name)
  File "/home/yyy/Desktop/app_with_git/app/telegram_bot/main_bot.py", line 92, in get_current_user_list_of_items_and_message
    database_data: List[AddedItemRow] = await get_query_from_added_users_item_table_with_username(SessionLocal, username)
  File "/home/yyy/Desktop/app_with_git/app/database_drivers/cruds.py", line 181, in get_query_from_added_users_item_table_with_username
    result.append(AddedItemRow(row.__dict__))
TypeError: __init__() takes 1 positional argument but 2 were given
INFO:telegram.ext.Application:Application is stopping. This might take a moment.
INFO:telegram.ext.Application:Application.stop() complete
INFO:telegram.ext.Application:Application started
INFO:__main__:Пользователь @golovinovY: запустить приложение
INFO:__main__:Пользователь @golovinovY: показать текущий список вещей
INFO:__main__:Пользователь @golovinovY: попытка удалить вещь из списка с сообщением 'Оплата'. Вещь не должна быть удалена
INFO:__main__:Пользователь @golovinovY: показать текущий список вещей
INFO:__main__:Пользователь @golovinovY: удалить вещь из списка с сообщением '3'
INFO:__main__:Пользователь @golovinovY: показать текущий список вещей
INFO:__main__:Пользователь @golovinovY: добавить вещь в список с сообщением 'Сдала'. Магазин: Rogov
INFO:__main__:Пользователь @golovinovY: добавить вещь в список с сообщением 'rogovshop1'. Магазин: Rogov
INFO:__main__:Пользователь @golovinovY: добавить вещь в список с сообщением 'rogovshop1789'. Магазин: Rogov
INFO:__main__:Пользователь @golovinovY: показать текущий список вещей
INFO:telegram.ext.Application:Application is stopping. This might take a moment.
INFO:telegram.ext.Application:Application.stop() complete
INFO:telegram.ext.Application:Application started
INFO:telegram.ext.Application:Application is stopping. This might take a moment.
INFO:telegram.ext.Application:Application.stop() complete
